test_0 (__main__.lab3a.test_0)
[Lab 3] - [Investigation 1] - [Part 4] - Functions - Test for file creation: ./lab3a.py ... FAIL

======================================================================
FAIL: test_0 (__main__.lab3a.test_0)
[Lab 3] - [Investigation 1] - [Part 4] - Functions - Test for file creation: ./lab3a.py
----------------------------------------------------------------------
Traceback (most recent call last):
  File "/home/ivan/ops445/lab3/lab3-demo/./CheckLab3.py", line 50, in test_0
    self.assertTrue(os.path.exists('./lab3a.py'), msg=error_output)
AssertionError: False is not true : your file cannot be found (HINT: make sure you AND your file are in the correct directory)

----------------------------------------------------------------------
Ran 1 test in 0.001s

FAILED (failures=1)
OPS445 Lab Report - System Information for running ./CheckLab3.py
=================================================================
    User login name: ivan
    Linux system name: ivan-VirtualBox
    Python executable: /usr/bin/python3
    Python version: 3123
    OS Platform: linux
    Working Directory: /home/ivan/ops445/lab3/lab3-demo
    Start at: Fri May 31 16:00:31 2024
=================================================================
